Workbook
Name Nom_Foyer: 'Paramètres'!$E$9
Name Responsable: 'Paramètres'!$E$10
Name Adresse_Entite: 'Paramètres'!$E$12
Name Ville_Entite: 'Paramètres'!$E$13
Name Pays_Entite: 'Paramètres'!$E$14
Name Tel_Entite: 'Paramètres'!$E$15
Name Email_Entite: 'Paramètres'!$E$16
Name Site_Entite: 'Paramètres'!$E$17
Name Devise_Base: 'Paramètres'!$E$24
Name Symbole_Base: 'Paramètres'!$E$26
Name Solde_Initial: 'Paramètres'!$E$33
Name Taux_Cible: 'Paramètres'!$E$34
Name Seuil_Alerte: 'Paramètres'!$E$35
Name Plafond_Mensuel: 'Paramètres'!$E$36
Name Liste_Comptes: 'Paramètres'!$C$41:$C$60
Name Annee_Travail: 'Tableau de Bord'!$D$4
Name Mois_Suivi: 'Tableau de Bord'!$G$4
Name Mois_Num: 'Tableau de Bord'!$H$4
Name Codes_Devises: 'Listes'!$B$6:$B$31
Name Noms_Devises: 'Listes'!$C$6:$C$31
Name Symboles_Devises: 'Listes'!$D$6:$D$31
Name Taux_Devises: 'Listes'!$G$6:$G$31
Name Facteurs_Frequence: 'Listes'!$AO$6:$AO$11
Name J_Date: 'Journal'!$B$13:$B$3012
Name J_Type: 'Journal'!$C$13:$C$3012
Name J_Module: 'Journal'!$D$13:$D$3012
Name J_Cat: 'Journal'!$E$13:$E$3012
Name J_Libelle: 'Journal'!$F$13:$F$3012
Name J_Compte: 'Journal'!$H$13:$H$3012
Name J_Entree: 'Journal'!$J$13:$J$3012
Name J_Sortie: 'Journal'!$K$13:$K$3012
Name J_Moyen: 'Journal'!$N$13:$N$3012
Name J_Projet: 'Journal'!$O$13:$O$3012
Name J_Nature: 'Journal'!$P$13:$P$3012
Name J_Statut: 'Journal'!$Q$13:$Q$3012
Name J_Montant: 'Journal'!$U$13:$U$3012
Name J_Mois: 'Journal'!$V$13:$V$3012
Name J_Annee: 'Journal'!$W$13:$W$3012
Name P_Annee: 'Estimation Annuelle'!$B$12:$B$211
Name P_Module: 'Estimation Annuelle'!$C$12:$C$211
Name P_Type: 'Estimation Annuelle'!$D$12:$D$211
Name P_Cat: 'Estimation Annuelle'!$E$12:$E$211
Name P_Total: 'Estimation Annuelle'!$R$12:$R$211
Name P_Mois: 'Estimation Annuelle'!$F$12:$Q$211
Name Liste_Projets: 'Calculs'!$B$246:$B$285
Name Dime_Active: 'Paramètres'!$E$68
Name Dime_Taux: 'Paramètres'!$E$69
Name Dime_Base: 'Paramètres'!$E$70
Name Perimetre: 'Paramètres'!$E$71
Name Perimetre_Filtre: 'Paramètres'!$K$71
Name P_M1: 'Estimation Annuelle'!$F$12:$F$211
Name P_M2: 'Estimation Annuelle'!$G$12:$G$211
Name P_M3: 'Estimation Annuelle'!$H$12:$H$211
Name P_M4: 'Estimation Annuelle'!$I$12:$I$211
Name P_M5: 'Estimation Annuelle'!$J$12:$J$211
Name P_M6: 'Estimation Annuelle'!$K$12:$K$211
Name P_M7: 'Estimation Annuelle'!$L$12:$L$211
Name P_M8: 'Estimation Annuelle'!$M$12:$M$211
Name P_M9: 'Estimation Annuelle'!$N$12:$N$211
Name P_M10: 'Estimation Annuelle'!$O$12:$O$211

Sheet Accueil
B7: Planification et suivi financier — général, mariage, immobilier & terrain, business
B9: ="Bonjour "&Nom_Foyer&" • période suivie : "&Mois_Suivi&" "&Annee_Travail&" • devise : "&Devise_Base&" ("&Symbole_Base&")"
B10: =TRIM(Adresse_Entite&IF(Adresse_Entite="","",", ")&Ville_Entite&IF(Pays_Entite="","",", "&Pays_Entite)&IF(Tel_Entite="",""," · "&Tel_Entite)&IF(Email_Entite="",""," · "&Email_Entite)&IF(Site_Entite="",""," · "&Site_Entite))
B12: VOTRE PARCOURS — DANS CET ORDRE
B13: ① REMPLIR MES INFORMATIONS | D13: ② ESTIMER MON ANNÉE | F13: ③ BUDGET SMART
B16: Nom, coordonnées, devise, comptes bancaires | D16: Charges fixes, variables et imprévus, mois par mois | F16: Mon journal de tous les jours — tout se synchronise
B18: Une fois vos informations et votre estimation posées, il ne reste plus qu'à tenir le journal : tableau de bord, budget 12 mois, synthèse et modules se remplissent tout seuls.
B20: MES MODULES — chacun sa feuille, aucun mélange
B21: MARIAGE | D21: PROJET | F21: IMMO
B23: Postes, devis, financement | D23: Business, chiffre d'affaires, marge | F23: Terrains, biens, travaux, loyers
B26: OÙ J'EN SUIS AUJOURD'HUI
B27: SOLDE DU MOIS | D27: DÉPENSES DU MOIS | F27: TRÉSORERIE DISPONIBLE
B28: =INDEX(Calculs!$J$6:$J$17,Mois_Num) | D28: =INDEX(Calculs!$E$6:$E$17,Mois_Num) | F28: =Paramètres!$H$61
B32: CONSULTER
B33: ➜ Tableau de bord | D33: ➜ Budget 12 mois | F33: ➜ Synthèse annuelle
B35: ➜ Objectifs & épargne | D35: ➜ Dettes & crédits | F35: ➜ Charges récurrentes
B37: ➜ Guide d'utilisation | D37: ➜ Référentiels & listes
B39: Les cases sur fond jaune pâle sont les seules à remplir. Tout le reste est calculé et verrouillé — mot de passe APEX-2026 si vous devez y toucher.
B42: APEX AFRICA — African Premium Experience · Abidjan, Côte d'Ivoire
B43: contact@apxafrica.com · www.apxafrica.com
B44: © 2026 APEX AFRICA. « Budget Smart » et son logo sont la propriété d'APEX AFRICA. Tous droits réservés — reproduction, diffusion ou revente interdites sans autorisation écrite.
B45: BUDGET SMART by APEX AFRICA v1.0 — feuilles protégées, aucune macro.

Sheet Paramètres
B1: MES INFORMATIONS
B2: Étape ① — renseignez ceci une seule fois : tout le classeur s'y adapte
B3: ⌂ ACCUEIL | D3: ① MES INFOS | F3: ② ESTIMATION | H3: ③ BUDGET SMART | J3: TABLEAU DE BORD
C5: Seules les cases sur fond JAUNE PÂLE sont modifiables. Le reste de la feuille est verrouillé pour protéger les formules — mot de passe APEX-2026 (Révision ▸ Ôter la protection de la feuille).
C7: ① IDENTITÉ & COORDONNÉES
C9: Raison sociale / Nom | E9: APEX AFRICA | G9: Apparaît en tête du tableau de bord et des synthèses.
C10: Responsable / Titulaire | G10: La personne qui tient le budget.
C11: Activité / Fonction
C12: Adresse
C13: Ville | E13: Abidjan
C14: Pays | E14: Côte d'Ivoire
C15: Téléphone | G15: Saisissez-le tel quel, avec l'indicatif : +225 …
C16: Email | E16: contact@apxafrica.com
C17: Site web | E17: www.apxafrica.com
C18: RCCM / IFU / N° d'identification | G18: Facultatif — utile si le classeur sert à une structure.
C19: Situation familiale | G19: Pour un budget personnel. Laissez vide sinon.
C20: Personnes à charge | E20: 0 | G20: Sert au calcul de la dépense moyenne par personne.
C22: ② DEVISE & PÉRIODE
C24: Devise de base | E24: XOF | G24: Toutes les synthèses sont exprimées dans cette devise. Changez-la : symboles, taux et totaux suivent. À fixer avant de commencer à saisir.
C25: Nom de la devise | E25: =IFERROR(INDEX(Noms_Devises,MATCH(Devise_Base,Codes_Devises,0)),"")
C26: Symbole | E26: =IFERROR(INDEX(Symboles_Devises,MATCH(Devise_Base,Codes_Devises,0)),"")
C27: Année de travail | E27: =Annee_Travail | G27: Se règle en haut du Tableau de bord — toutes les feuilles suivent.
C28: Mois de suivi | E28: =Mois_Suivi | G28: Se règle également en haut du Tableau de bord.
C29: Mois de démarrage du budget | E29: Janvier | G29: Utile si votre exercice ne démarre pas en janvier.
C31: ③ SOLDES & OBJECTIFS
C33: Trésorerie initiale | E33: 0 | G33: Total de vos disponibilités au 1er janvier de l'année de travail.
C34: Taux d'épargne cible | E34: 0.2 | G34: Part des revenus que vous visez à épargner chaque mois.
C35: Seuil d'alerte budget | E35: 0.9 | G35: Au-delà de ce pourcentage du budget consommé, l'alerte passe au rouge.
C36: Plafond de dépenses mensuel | E36: 0 | G36: Laissez 0 si vous n'en fixez pas.
C38: ④ COMPTES, CAISSES & PORTEFEUILLES
C40: Compte / Portefeuille | D40: Nature | E40: Devise | F40: Solde d'ouverture | G40: Mouvements enregistrés | H40: Solde actuel calculé
C41: Compte courant principal | E41: =IF($C41="","",Devise_Base) | F41: 0 | G41: =IF($C41="","",SUMIFS(J_Montant,J_Compte,$C41,J_Type,"Revenu",J_Statut,"<>Annulé",J_Statut,"<>Prévu")-SUMIFS(J_Montant,J_Compte,$C41,J_Type,"Dépense",J_Statut,"<>Annulé",J_Statut,"<>Prévu")-SUMIFS(J_Montant,J_Compte,$C41,J_Type,"Épargne",J_Statut,"<>Annulé",J_Statut,"<>Prévu")-SUMIFS(J_Montant,J_Compte,$C41,J_Type,"Investissement",J_Statut,"<>Annulé",J_Statut,"<>Prévu")-SUMIFS(J_Montant,J_Compte,$C41,J_Type,"Remboursement crédit",J_Statut,"<>Annulé",J_Statut,"<>Prévu")) | H41: =IF($C41="","",N($F41)+N($G41))
C42: Compte courant secondaire | E42: =IF($C42="","",Devise_Base) | F42: 0 | G42: =IF($C42="","",SUMIFS(J_Montant,J_Compte,$C42,J_Type,"Revenu",J_Statut,"<>Annulé",J_Statut,"<>Prévu")-SUMIFS(J_Montant,J_Compte,$C42,J_Type,"Dépense",J_Statut,"<>Annulé",J_Statut,"<>Prévu")-SUMIFS(J_Montant,J_Compte,$C42,J_Type,"Épargne",J_Statut,"<>Annulé",J_Statut,"<>Prévu")-SUMIFS(J_Montant,J_Compte,$C42,J_Type,"Investissement",J_Statut,"<>Annulé",J_Statut,"<>Prévu")-SUMIFS(J_Montant,J_Compte,$C42,J_Type,"Remboursement crédit",J_Statut,"<>Annulé",J_Statut,"<>Prévu")) | H42: =IF($C42="","",N($F42)+N($G42))
C43: Mobile Money 1 | E43: =IF($C43="","",Devise_Base) | F43: 0 | G43: =IF($C43="","",SUMIFS(J_Montant,J_Compte,$C43,J_Type,"Revenu",J_Statut,"<>Annulé",J_Statut,"<>Prévu")-SUMIFS(J_Montant,J_Compte,$C43,J_Type,"Dépense",J_Statut,"<>Annulé",J_Statut,"<>Prévu")-SUMIFS(J_Montant,J_Compte,$C43,J_Type,"Épargne",J_Statut,"<>Annulé",J_Statut,"<>Prévu")-SUMIFS(J_Montant,J_Compte,$C43,J_Type,"Investissement",J_Statut,"<>Annulé",J_Statut,"<>Prévu")-SUMIFS(J_Montant,J_Compte,$C43,J_Type,"Remboursement crédit",J_Statut,"<>Annulé",J_Statut,"<>Prévu")) | H43: =IF($C43="","",N($F43)+N($G43))
C44: Mobile Money 2 | E44: =IF($C44="","",Devise_Base) | F44: 0 | G44: =IF($C44="","",SUMIFS(J_Montant,J_Compte,$C44,J_Type,"Revenu",J_Statut,"<>Annulé",J_Statut,"<>Prévu")-SUMIFS(J_Montant,J_Compte,$C44,J_Type,"Dépense",J_Statut,"<>Annulé",J_Statut,"<>Prévu")-SUMIFS(J_Montant,J_Compte,$C44,J_Type,"Épargne",J_Statut,"<>Annulé",J_Statut,"<>Prévu")-SUMIFS(J_Montant,J_Compte,$C44,J_Type,"Investissement",J_Statut,"<>Annulé",J_Statut,"<>Prévu")-SUMIFS(J_Montant,J_Compte,$C44,J_Type,"Remboursement crédit",J_Statut,"<>Annulé",J_Statut,"<>Prévu")) | H44: =IF($C44="","",N($F44)+N($G44))
C45: Espèces / Caisse | E45: =IF($C45="","",Devise_Base) | F45: 0 | G45: =IF($C45="","",SUMIFS(J_Montant,J_Compte,$C45,J_Type,"Revenu",J_Statut,"<>Annulé",J_Statut,"<>Prévu")-SUMIFS(J_Montant,J_Compte,$C45,J_Type,"Dépense",J_Statut,"<>Annulé",J_Statut,"<>Prévu")-SUMIFS(J_Montant,J_Compte,$C45,J_Type,"Épargne",J_Statut,"<>Annulé",J_Statut,"<>Prévu")-SUMIFS(J_Montant,J_Compte,$C45,J_Type,"Investissement",J_Statut,"<>Annulé",J_Statut,"<>Prévu")-SUMIFS(J_Montant,J_Compte,$C45,J_Type,"Remboursement crédit",J_Statut,"<>Annulé",J_Statut,"<>Prévu")) | H45: =IF($C45="","",N($F45)+N($G45))
C46: Compte épargne | E46: =IF($C46="","",Devise_Base) | F46: 0 | G46: =IF($C46="","",SUMIFS(J_Montant,J_Compte,$C46,J_Type,"Revenu",J_Statut,"<>Annulé",J_Statut,"<>Prévu")-SUMIFS(J_Montant,J_Compte,$C46,J_Type,"Dépense",J_Statut,"<>Annulé",J_Statut,"<>Prévu")-SUMIFS(J_Montant,J_Compte,$C46,J_Type,"Épargne",J_Statut,"<>Annulé",J_Statut,"<>Prévu")-SUMIFS(J_Montant,J_Compte,$C46,J_Type,"Investissement",J_Statut,"<>Annulé",J_Statut,"<>Prévu")-SUMIFS(J_Montant,J_Compte,$C46,J_Type,"Remboursement crédit",J_Statut,"<>Annulé",J_Statut,"<>Prévu")) | H46: =IF($C46="","",N($F46)+N($G46))
C47: Compte projet | E47: =IF($C47="","",Devise_Base) | F47: 0 | G47: =IF($C47="","",SUMIFS(J_Montant,J_Compte,$C47,J_Type,"Revenu",J_Statut,"<>Annulé",J_Statut,"<>Prévu")-SUMIFS(J_Montant,J_Compte,$C47,J_Type,"Dépense",J_Statut,"<>Annulé",J_Statut,"<>Prévu")-SUMIFS(J_Montant,J_Compte,$C47,J_Type,"Épargne",J_Statut,"<>Annulé",J_Statut,"<>Prévu")-SUMIFS(J_Montant,J_Compte,$C47,J_Type,"Investissement",J_Statut,"<>Annulé",J_Statut,"<>Prévu")-SUMIFS(J_Montant,J_Compte,$C47,J_Type,"Remboursement crédit",J_Statut,"<>Annulé",J_Statut,"<>Prévu")) | H47: =IF($C47="","",N($F47)+N($G47))
C48: Compte business | E48: =IF($C48="","",Devise_Base) | F48: 0 | G48: =IF($C48="","",SUMIFS(J_Montant,J_Compte,$C48,J_Type,"Revenu",J_Statut,"<>Annulé",J_Statut,"<>Prévu")-SUMIFS(J_Montant,J_Compte,$C48,J_Type,"Dépense",J_Statut,"<>Annulé",J_Statut,"<>Prévu")-SUMIFS(J_Montant,J_Compte,$C48,J_Type,"Épargne",J_Statut,"<>Annulé",J_Statut,"<>Prévu")-SUMIFS(J_Montant,J_Compte,$C48,J_Type,"Investissement",J_Statut,"<>Annulé",J_Statut,"<>Prévu")-SUMIFS(J_Montant,J_Compte,$C48,J_Type,"Remboursement crédit",J_Statut,"<>Annulé",J_Statut,"<>Prévu")) | H48: =IF($C48="","",N($F48)+N($G48))
E49: =IF($C49="","",Devise_Base) | G49: =IF($C49="","",SUMIFS(J_Montant,J_Compte,$C49,J_Type,"Revenu",J_Statut,"<>Annulé",J_Statut,"<>Prévu")-SUMIFS(J_Montant,J_Compte,$C49,J_Type,"Dépense",J_Statut,"<>Annulé",J_Statut,"<>Prévu")-SUMIFS(J_Montant,J_Compte,$C49,J_Type,"Épargne",J_Statut,"<>Annulé",J_Statut,"<>Prévu")-SUMIFS(J_Montant,J_Compte,$C49,J_Type,"Investissement",J_Statut,"<>Annulé",J_Statut,"<>Prévu")-SUMIFS(J_Montant,J_Compte,$C49,J_Type,"Remboursement crédit",J_Statut,"<>Annulé",J_Statut,"<>Prévu")) | H49: =IF($C49="","",N($F49)+N($G49))
...

Sheet Estimation Annuelle
B1: ESTIMATION ANNUELLE
B2: Étape ② — ce que vous prévoyez pour l'année, mois par mois. Le réalisé remonte tout seul du Journal.
B3: ⌂ ACCUEIL | E3: ① MES INFOS | H3: ② ESTIMATION | K3: ③ BUDGET SMART | N3: TABLEAU DE BORD | Q3: BUDGET 12 MOIS
B5: Une ligne = une catégorie budgétée pour une année. Dupliquez les lignes en changeant l'année pour préparer l'exercice suivant : l'historique reste intact. « Écart » est toujours favorable quand il est positif.
B7: REVENUS PRÉVUS | E7: DÉPENSES PRÉVUES | H7: ÉPARGNE PRÉVUE | K7: SOLDE PRÉVISIONNEL | N7: RÉALISÉ / PRÉVU (dépenses)
B8: =SUMIFS($R$12:$R$211,$B$12:$B$211,Annee_Travail,$D$12:$D$211,"Revenu") | E8: =SUMIFS($R$12:$R$211,$B$12:$B$211,Annee_Travail,$D$12:$D$211,"Dépense") | H8: =SUMIFS($R$12:$R$211,$B$12:$B$211,Annee_Travail,$D$12:$D$211,"Épargne")+SUMIFS($R$12:$R$211,$B$12:$B$211,Annee_Travail,$D$12:$D$211,"Investissement") | K8: =SUMIFS($R$12:$R$211,$B$12:$B$211,Annee_Travail,$D$12:$D$211,"Revenu")-SUMIFS($R$12:$R$211,$B$12:$B$211,Annee_Travail,$D$12:$D$211,"Dépense")-SUMIFS($R$12:$R$211,$B$12:$B$211,Annee_Travail,$D$12:$D$211,"Remboursement crédit") | N8: =IFERROR(SUMIFS($S$12:$S$211,$B$12:$B$211,Annee_Travail,$D$12:$D$211,"Dépense")/SUMIFS($R$12:$R$211,$B$12:$B$211,Annee_Travail,$D$12:$D$211,"Dépense"),0)
B11: Année | C11: Module | D11: Type | E11: Catégorie | F11: Jan | G11: Fév | H11: Mar | I11: Avr | J11: Mai | K11: Juin | L11: Juil | M11: Août | N11: Sep | O11: Oct | P11: Nov | Q11: Déc | R11: Total prévu | S11: Réalisé | T11: Écart | U11: % consommé | V11: Commentaire
B12: =Annee_Travail | C12: Général | D12: Revenu | E12: Salaire | R12: =IF($E12="","",SUM($F12:$Q12)) | S12: =IF($E12="","",SUMIFS(J_Montant,J_Annee,$B12,J_Module,$C12,J_Type,$D12,J_Cat,$E12,J_Statut,"<>Annulé",J_Statut,"<>Prévu")) | T12: =IF($E12="","",IF($D12="Revenu",$S12-$R12,$R12-$S12)) | U12: =IF(OR($E12="",$R12=0),"",$S12/$R12)
B13: =Annee_Travail | C13: Général | D13: Revenu | E13: Prime / 13e mois | R13: =IF($E13="","",SUM($F13:$Q13)) | S13: =IF($E13="","",SUMIFS(J_Montant,J_Annee,$B13,J_Module,$C13,J_Type,$D13,J_Cat,$E13,J_Statut,"<>Annulé",J_Statut,"<>Prévu")) | T13: =IF($E13="","",IF($D13="Revenu",$S13-$R13,$R13-$S13)) | U13: =IF(OR($E13="",$R13=0),"",$S13/$R13)
B14: =Annee_Travail | C14: Général | D14: Revenu | E14: Freelance / Consulting | R14: =IF($E14="","",SUM($F14:$Q14)) | S14: =IF($E14="","",SUMIFS(J_Montant,J_Annee,$B14,J_Module,$C14,J_Type,$D14,J_Cat,$E14,J_Statut,"<>Annulé",J_Statut,"<>Prévu")) | T14: =IF($E14="","",IF($D14="Revenu",$S14-$R14,$R14-$S14)) | U14: =IF(OR($E14="",$R14=0),"",$S14/$R14)
B15: =Annee_Travail | C15: Général | D15: Revenu | E15: Commerce / Ventes | R15: =IF($E15="","",SUM($F15:$Q15)) | S15: =IF($E15="","",SUMIFS(J_Montant,J_Annee,$B15,J_Module,$C15,J_Type,$D15,J_Cat,$E15,J_Statut,"<>Annulé",J_Statut,"<>Prévu")) | T15: =IF($E15="","",IF($D15="Revenu",$S15-$R15,$R15-$S15)) | U15: =IF(OR($E15="",$R15=0),"",$S15/$R15)
B16: =Annee_Travail | C16: Général | D16: Revenu | E16: Loyers perçus | R16: =IF($E16="","",SUM($F16:$Q16)) | S16: =IF($E16="","",SUMIFS(J_Montant,J_Annee,$B16,J_Module,$C16,J_Type,$D16,J_Cat,$E16,J_Statut,"<>Annulé",J_Statut,"<>Prévu")) | T16: =IF($E16="","",IF($D16="Revenu",$S16-$R16,$R16-$S16)) | U16: =IF(OR($E16="",$R16=0),"",$S16/$R16)
B17: =Annee_Travail | C17: Général | D17: Revenu | E17: Autre revenu | R17: =IF($E17="","",SUM($F17:$Q17)) | S17: =IF($E17="","",SUMIFS(J_Montant,J_Annee,$B17,J_Module,$C17,J_Type,$D17,J_Cat,$E17,J_Statut,"<>Annulé",J_Statut,"<>Prévu")) | T17: =IF($E17="","",IF($D17="Revenu",$S17-$R17,$R17-$S17)) | U17: =IF(OR($E17="",$R17=0),"",$S17/$R17)
B18: =Annee_Travail | C18: Général | D18: Dépense | E18: Loyer | R18: =IF($E18="","",SUM($F18:$Q18)) | S18: =IF($E18="","",SUMIFS(J_Montant,J_Annee,$B18,J_Module,$C18,J_Type,$D18,J_Cat,$E18,J_Statut,"<>Annulé",J_Statut,"<>Prévu")) | T18: =IF($E18="","",IF($D18="Revenu",$S18-$R18,$R18-$S18)) | U18: =IF(OR($E18="",$R18=0),"",$S18/$R18)
B19: =Annee_Travail | C19: Général | D19: Dépense | E19: Électricité | R19: =IF($E19="","",SUM($F19:$Q19)) | S19: =IF($E19="","",SUMIFS(J_Montant,J_Annee,$B19,J_Module,$C19,J_Type,$D19,J_Cat,$E19,J_Statut,"<>Annulé",J_Statut,"<>Prévu")) | T19: =IF($E19="","",IF($D19="Revenu",$S19-$R19,$R19-$S19)) | U19: =IF(OR($E19="",$R19=0),"",$S19/$R19)
B20: =Annee_Travail | C20: Général | D20: Dépense | E20: Eau | R20: =IF($E20="","",SUM($F20:$Q20)) | S20: =IF($E20="","",SUMIFS(J_Montant,J_Annee,$B20,J_Module,$C20,J_Type,$D20,J_Cat,$E20,J_Statut,"<>Annulé",J_Statut,"<>Prévu")) | T20: =IF($E20="","",IF($D20="Revenu",$S20-$R20,$R20-$S20)) | U20: =IF(OR($E20="",$R20=0),"",$S20/$R20)
B21: =Annee_Travail | C21: Général | D21: Dépense | E21: Internet / Box | R21: =IF($E21="","",SUM($F21:$Q21)) | S21: =IF($E21="","",SUMIFS(J_Montant,J_Annee,$B21,J_Module,$C21,J_Type,$D21,J_Cat,$E21,J_Statut,"<>Annulé",J_Statut,"<>Prévu")) | T21: =IF($E21="","",IF($D21="Revenu",$S21-$R21,$R21-$S21)) | U21: =IF(OR($E21="",$R21=0),"",$S21/$R21)
B22: =Annee_Travail | C22: Général | D22: Dépense | E22: Téléphone | R22: =IF($E22="","",SUM($F22:$Q22)) | S22: =IF($E22="","",SUMIFS(J_Montant,J_Annee,$B22,J_Module,$C22,J_Type,$D22,J_Cat,$E22,J_Statut,"<>Annulé",J_Statut,"<>Prévu")) | T22: =IF($E22="","",IF($D22="Revenu",$S22-$R22,$R22-$S22)) | U22: =IF(OR($E22="",$R22=0),"",$S22/$R22)
B23: =Annee_Travail | C23: Général | D23: Dépense | E23: Alimentation / Courses | R23: =IF($E23="","",SUM($F23:$Q23)) | S23: =IF($E23="","",SUMIFS(J_Montant,J_Annee,$B23,J_Module,$C23,J_Type,$D23,J_Cat,$E23,J_Statut,"<>Annulé",J_Statut,"<>Prévu")) | T23: =IF($E23="","",IF($D23="Revenu",$S23-$R23,$R23-$S23)) | U23: =IF(OR($E23="",$R23=0),"",$S23/$R23)
... B78: =Annee_Travail | C78: Business | D78: Dépense | E78: Divers business | R78: =IF($E78="","",SUM($F78:$Q78)) | S78: =IF($E78="","",SUMIFS(J_Montant,J_Annee,$B78,J_Module,$C78,J_Type,$D78,J_Cat,$E78,J_Statut,"<>Annulé",J_Statut,"<>Prévu")) | T78: =IF($E78="","",IF($D78="Revenu",$S78-$R78,$R78-$S78)) | U78: =IF(OR($E78="",$R78=0),"",$S78/$R78)
B79: =Annee_Travail | R79: =IF($E79="","",SUM($F79:$Q79)) | S79: =IF($E79="","",SUMIFS(J_Montant,J_Annee,$B79,J_Module,$C79,J_Type,$D79,J_Cat,$E79,J_Statut,"<>Annulé",J_Statut,"<>Prévu")) | T79: =IF($E79="","",IF($D79="Revenu",$S79-$R79,$R79-$S79)) | U79: =IF(OR($E79="",$R79=0),"",$S79/$R79)
B80: =Annee_Travail | R80: =IF($E80="","",SUM($F80:$Q80)) | S80: =IF($E80="","",SUMIFS(J_Montant,J_Annee,$B80,J_Module,$C80,J_Type,$D80,J_Cat,$E80,J_Statut,"<>Annulé",J_Statut,"<>Prévu")) | T80: =IF($E80="","",IF($D80="Revenu",$S80-$R80,$R80-$S80)) | U80: =IF(OR($E80="",$R80=0),"",$S80/$R80)
B81: =Annee_Travail | R81: =IF($E81="","",SUM($F81:$Q81)) | S81: =IF($E81="","",SUMIFS(J_Montant,J_Annee,$B81,J_Module,$C81,J_Type,$D81,J_Cat,$E81,J_Statut,"<>Annulé",J_Statut,"<>Prévu")) | T81: =IF($E81="","",IF($D81="Revenu",$S81-$R81,$R81-$S81)) | U81: =IF(OR($E81="",$R81=0),"",$S81/$R81)
B82: =Annee_Travail | R82: =IF($E82="","",SUM($F82:$Q82)) | S82: =IF($E82="","",SUMIFS(J_Montant,J_Annee,$B82,J_Module,$C82,J_Type,$D82,J_Cat,$E82,J_Statut,"<>Annulé",J_Statut,"<>Prévu")) | T82: =IF($E82="","",IF($D82="Revenu",$S82-$R82,$R82-$S82)) | U82: =IF(OR($E82="",$R82=0),"",$S82/$R82)
B83: =Annee_Travail | R83: =IF($E83="","",SUM($F83:$Q83)) | S83: =IF($E83="","",SUMIFS(J_Montant,J_Annee,$B83,J_Module,$C83,J_Type,$D83,J_Cat,$E83,J_Statut,"<>Annulé",J_Statut,"<>Prévu")) | T83: =IF($E83="","",IF($D83="Revenu",$S83-$R83,$R83-$S83)) | U83: =IF(OR($E83="",$R83=0),"",$S83/$R83)
B84: =Annee_Travail | R84: =IF($E84="","",SUM($F84:$Q84)) | S84: =IF($E84="","",SUMIFS(J_Montant,J_Annee,$B84,J_Module,$C84,J_Type,$D84,J_Cat,$E84,J_Statut,"<>Annulé",J_Statut,"<>Prévu")) | T84: =IF($E84="","",IF($D84="Revenu",$S84-$R84,$R84-$S84)) | U84: =IF(OR($E84="",$R84=0),"",$S84/$R84)
B85: =Annee_Travail | R85: =IF($E85="","",SUM($F85:$Q85)) | S85: =IF($E85="","",SUMIFS(J_Montant,J_Annee,$B85,J_Module,$C85,J_Type,$D85,J_Cat,$E85,J_Statut,"<>Annulé",J_Statut,"<>Prévu")) | T85: =IF($E85="","",IF($D85="Revenu",$S85-$R85,$R85-$S85)) | U85: =IF(OR($E85="",$R85=0),"",$S85/$R85)
B86: =Annee_Travail | R86: =IF($E86="","",SUM($F86:$Q86)) | S86: =IF($E86="","",SUMIFS(J_Montant,J_Annee,$B86,J_Module,$C86,J_Type,$D86,J_Cat,$E86,J_Statut,"<>Annulé",J_Statut,"<>Prévu")) | T86: =IF($E86="","",IF($D86="Revenu",$S86-$R86,$R86-$S86)) | U86: =IF(OR($E86="",$R86=0),"",$S86/$R86)
B87: =Annee_Travail | R87: =IF($E87="","",SUM($F87:$Q87)) | S87: =IF($E87="","",SUMIFS(J_Montant,J_Annee,$B87,J_Module,$C87,J_Type,$D87,J_Cat,$E87,J_Statut,"<>Annulé",J_Statut,"<>Prévu")) | T87: =IF($E87="","",IF($D87="Revenu",$S87-$R87,$R87-$S87)) | U87: =IF(OR($E87="",$R87=0),"",$S87/$R87)
B88: =Annee_Travail | R88: =IF($E88="","",SUM($F88:$Q88)) | S88: =IF($E88="","",SUMIFS(J_Montant,J_Annee,$B88,J_Module,$C88,J_Type,$D88,J_Cat,$E88,J_Statut,"<>Annulé",J_Statut,"<>Prévu")) | T88: =IF($E88="","",IF($D88="Revenu",$S88-$R88,$R88-$S88)) | U88: =IF(OR($E88="",$R88=0),"",$S88/$R88)
B89: =Annee_Travail | R89: =IF($E89="","",SUM($F89:$Q89)) | S89: =IF($E89="","",SUMIFS(J_Montant,J_Annee,$B89,J_Module,$C89,J_Type,$D89,J_Cat,$E89,J_Statut,"<>Annulé",J_Statut,"<>Prévu")) | T89: =IF($E89="","",IF($D89="Revenu",$S89-$R89,$R89-$S89)) | U89: =IF(OR($E89="",$R89=0),"",$S89/$R89)
B90: =Annee_Travail | R90: =IF($E90="","",SUM($F90:$Q90)) | S90: =IF($E90="","",SUMIFS(J_Montant,J_Annee,$B90,J_Module,$C90,J_Type,$D90,J_Cat,$E90,J_Statut,"<>Annulé",J_Statut,"<>Prévu")) | T90: =IF($E90="","",IF($D90="Revenu",$S90-$R90,$R90-$S90)) | U90: =IF(OR($E90="",$R90=0),"",$S90/$R90)
... B211: =Annee_Travail | R211: =IF($E211="","",SUM($F211:$Q211)) | S211: =IF($E211="","",SUMIFS(J_Montant,J_Annee,$B211,J_Module,$C211,J_Type,$D211,J_Cat,$E211,J_Statut,"<>Annulé",J_Statut,"<>Prévu")) | T211: =IF($E211="","",IF($D211="Revenu",$S211-$R211,$R211-$S211)) | U211: =IF(OR($E211="",$R211=0),"",$S211/$R211)

Sheet Journal
B1: BUDGET SMART — JOURNAL QUOTIDIEN
B2: Une ligne par opération. Vous ne remplissez que le premier bloc ; le sens, l'entrée, la sortie et le solde se calculent seuls.
B3: ⌂ ACCUEIL | E3: ① MES INFOS | H3: ② ESTIMATION | K3: ③ BUDGET SMART | N3: TABLEAU DE BORD | Q3: BUDGET 12 MOIS
B5: Saisissez toujours un montant POSITIF dans « Montant ». C'est la colonne « Type » qui dit si l'argent entre ou sort : le classeur remplit alors tout seul les colonnes ENTRÉE, SORTIE et SOLDE CUMULÉ. Statut « Prévu » = engagement futur, compté à part. Les cases jaunes sont les seules à remplir.
B7: ÉCRITURES SAISIES | E7: TOTAL DES ENTRÉES | H7: TOTAL DES SORTIES | K7: SOLDE DE L'ANNÉE | N7: MIS DE CÔTÉ | Q7: EN ATTENTE / PRÉVU
B8: =COUNT(J_Date) | E8: =SUMIFS(J_Montant,J_Annee,Annee_Travail,J_Type,"Revenu",J_Statut,"<>Annulé",J_Statut,"<>Prévu") | H8: =SUMIFS(J_Montant,J_Annee,Annee_Travail,J_Type,"<>Revenu",J_Type,"<>Transfert",J_Statut,"<>Annulé",J_Statut,"<>Prévu") | K8: =SUMIFS(J_Montant,J_Annee,Annee_Travail,J_Type,"Revenu",J_Statut,"<>Annulé",J_Statut,"<>Prévu")-SUMIFS(J_Montant,J_Annee,Annee_Travail,J_Type,"<>Revenu",J_Type,"<>Transfert",J_Statut,"<>Annulé",J_Statut,"<>Prévu") | N8: =SUMIFS(J_Montant,J_Annee,Annee_Travail,J_Type,"Épargne",J_Statut,"<>Annulé",J_Statut,"<>Prévu")+SUMIFS(J_Montant,J_Annee,Annee_Travail,J_Type,"Investissement",J_Statut,"<>Annulé",J_Statut,"<>Prévu") | Q8: =SUMIFS(J_Montant,J_Annee,Annee_Travail,J_Statut,"Prévu")+SUMIFS(J_Montant,J_Annee,Annee_Travail,J_Statut,"En attente")
B9: ="Dernière saisie : "&IF(COUNT(J_Date)=0,"—",RIGHT("0"&DAY(MAX(J_Date)),2)&"/"&RIGHT("0"&MONTH(MAX(J_Date)),2)&"/"&YEAR(MAX(J_Date))) | E9: ="Année "&Annee_Travail | H9: Dépenses + épargne + crédits | N9: Épargne + investissement | Q9: Engagements non décaissés
B11: ① À REMPLIR | I11: ② CALCULÉ POUR VOUS | M11: ③ COMPLÉMENTS — facultatifs | T11: ④ TECHNIQUE
B12: Date | C12: Type d'opération | D12: Module | E12: Catégorie | F12: Libellé / Description | G12: Montant | H12: Compte | I12: Sens | J12: ENTRÉE | K12: SORTIE | L12: Solde cumulé | M12: Devise | N12: Moyen de paiement | O12: Projet / Bien | P12: Nature | Q12: Statut | R12: Récurrent | S12: Notes | T12: Taux | U12: Montant (devise de base) | V12: Mois | W12: Année
I13: =IF($C13="","",IFERROR(INDEX(Sens_Types,MATCH($C13,Liste_Types,0)),"")) | J13: =IF($I13="▲ ENTRÉE",$U13,"") | K13: =IF($I13="▼ SORTIE",$U13,"") | L13: =Solde_Initial+N($J13)-N($K13) | T13: =IF($G13="","",IFERROR(INDEX(Taux_Devises,MATCH(IF($M13="",Devise_Base,$M13),Codes_Devises,0)),1)) | U13: =IF($G13="","",ROUND($G13*$T13,2)) | V13: =IF($B13="","",MONTH($B13)) | W13: =IF($B13="","",YEAR($B13))
I14: =IF($C14="","",IFERROR(INDEX(Sens_Types,MATCH($C14,Liste_Types,0)),"")) | J14: =IF($I14="▲ ENTRÉE",$U14,"") | K14: =IF($I14="▼ SORTIE",$U14,"") | L14: =$L13+N($J14)-N($K14) | T14: =IF($G14="","",IFERROR(INDEX(Taux_Devises,MATCH(IF($M14="",Devise_Base,$M14),Codes_Devises,0)),1)) | U14: =IF($G14="","",ROUND($G14*$T14,2)) | V14: =IF($B14="","",MONTH($B14)) | W14: =IF($B14="","",YEAR($B14))
I15: =IF($C15="","",IFERROR(INDEX(Sens_Types,MATCH($C15,Liste_Types,0)),"")) | J15: =IF($I15="▲ ENTRÉE",$U15,"") | K15: =IF($I15="▼ SORTIE",$U15,"") | L15: =$L14+N($J15)-N($K15) | T15: =IF($G15="","",IFERROR(INDEX(Taux_Devises,MATCH(IF($M15="",Devise_Base,$M15),Codes_Devises,0)),1)) | U15: =IF($G15="","",ROUND($G15*$T15,2)) | V15: =IF($B15="","",MONTH($B15)) | W15: =IF($B15="","",YEAR($B15))
I16: =IF($C16="","",IFERROR(INDEX(Sens_Types,MATCH($C16,Liste_Types,0)),"")) | J16: =IF($I16="▲ ENTRÉE",$U16,"") | K16: =IF($I16="▼ SORTIE",$U16,"") | L16: =$L15+N($J16)-N($K16) | T16: =IF($G16="","",IFERROR(INDEX(Taux_Devises,MATCH(IF($M16="",Devise_Base,$M16),Codes_Devises,0)),1)) | U16: =IF($G16="","",ROUND($G16*$T16,2)) | V16: =IF($B16="","",MONTH($B16)) | W16: =IF($B16="","",YEAR($B16))
I17: =IF($C17="","",IFERROR(INDEX(Sens_Types,MATCH($C17,Liste_Types,0)),"")) | J17: =IF($I17="▲ ENTRÉE",$U17,"") | K17: =IF($I17="▼ SORTIE",$U17,"") | L17: =$L16+N($J17)-N($K17) | T17: =IF($G17="","",IFERROR(INDEX(Taux_Devises,MATCH(IF($M17="",Devise_Base,$M17),Codes_Devises,0)),1)) | U17: =IF($G17="","",ROUND($G17*$T17,2)) | V17: =IF($B17="","",MONTH($B17)) | W17: =IF($B17="","",YEAR($B17))
I18: =IF($C18="","",IFERROR(INDEX(Sens_Types,MATCH($C18,Liste_Types,0)),"")) | J18: =IF($I18="▲ ENTRÉE",$U18,"") | K18: =IF($I18="▼ SORTIE",$U18,"") | L18: =$L17+N($J18)-N($K18) | T18: =IF($G18="","",IFERROR(INDEX(Taux_Devises,MATCH(IF($M18="",Devise_Base,$M18),Codes_Devises,0)),1)) | U18: =IF($G18="","",ROUND($G18*$T18,2)) | V18: =IF($B18="","",MONTH($B18)) | W18: =IF($B18="","",YEAR($B18))
I19: =IF($C19="","",IFERROR(INDEX(Sens_Types,MATCH($C19,Liste_Types,0)),"")) | J19: =IF($I19="▲ ENTRÉE",$U19,"") | K19: =IF($I19="▼ SORTIE",$U19,"") | L19: =$L18+N($J19)-N($K19) | T19: =IF($G19="","",IFERROR(INDEX(Taux_Devises,MATCH(IF($M19="",Devise_Base,$M19),Codes_Devises,0)),1)) | U19: =IF($G19="","",ROUND($G19*$T19,2)) | V19: =IF($B19="","",MONTH($B19)) | W19: =IF($B19="","",YEAR($B19))
I20: =IF($C20="","",IFERROR(INDEX(Sens_Types,MATCH($C20,Liste_Types,0)),"")) | J20: =IF($I20="▲ ENTRÉE",$U20,"") | K20: =IF($I20="▼ SORTIE",$U20,"") | L20: =$L19+N($J20)-N($K20) | T20: =IF($G20="","",IFERROR(INDEX(Taux_Devises,MATCH(IF($M20="",Devise_Base,$M20),Codes_Devises,0)),1)) | U20: =IF($G20="","",ROUND($G20*$T20,2)) | V20: =IF($B20="","",MONTH($B20)) | W20: =IF($B20="","",YEAR($B20))
I21: =IF($C21="","",IFERROR(INDEX(Sens_Types,MATCH($C21,Liste_Types,0)),"")) | J21: =IF($I21="▲ ENTRÉE",$U21,"") | K21: =IF($I21="▼ SORTIE",$U21,"") | L21: =$L20+N($J21)-N($K21) | T21: =IF($G21="","",IFERROR(INDEX(Taux_Devises,MATCH(IF($M21="",Devise_Base,$M21),Codes_Devises,0)),1)) | U21: =IF($G21="","",ROUND($G21*$T21,2)) | V21: =IF($B21="","",MONTH($B21)) | W21: =IF($B21="","",YEAR($B21))
I22: =IF($C22="","",IFERROR(INDEX(Sens_Types,MATCH($C22,Liste_Types,0)),"")) | J22: =IF($I22="▲ ENTRÉE",$U22,"") | K22: =IF($I22="▼ SORTIE",$U22,"") | L22: =$L21+N($J22)-N($K22) | T22: =IF($G22="","",IFERROR(INDEX(Taux_Devises,MATCH(IF($M22="",Devise_Base,$M22),Codes_Devises,0)),1)) | U22: =IF($G22="","",ROUND($G22*$T22,2)) | V22: =IF($B22="","",MONTH($B22)) | W22: =IF($B22="","",YEAR($B22))
I23: =IF($C23="","",IFERROR(INDEX(Sens_Types,MATCH($C23,Liste_Types,0)),"")) | J23: =IF($I23="▲ ENTRÉE",$U23,"") | K23: =IF($I23="▼ SORTIE",$U23,"") | L23: =$L22+N($J23)-N($K23) | T23: =IF($G23="","",IFERROR(INDEX(Taux_Devises,MATCH(IF($M23="",Devise_Base,$M23),Codes_Devises,0)),1)) | U23: =IF($G23="","",ROUND($G23*$T23,2)) | V23: =IF($B23="","",MONTH($B23)) | W23: =IF($B23="","",YEAR($B23))
I24: =IF($C24="","",IFERROR(INDEX(Sens_Types,MATCH($C24,Liste_Types,0)),"")) | J24: =IF($I24="▲ ENTRÉE",$U24,"") | K24: =IF($I24="▼ SORTIE",$U24,"") | L24: =$L23+N($J24)-N($K24) | T24: =IF($G24="","",IFERROR(INDEX(Taux_Devises,MATCH(IF($M24="",Devise_Base,$M24),Codes_Devises,0)),1)) | U24: =IF($G24="","",ROUND($G24*$T24,2)) | V24: =IF($B24="","",MONTH($B24)) | W24: =IF($B24="","",YEAR($B24))
I25: =IF($C25="","",IFERROR(INDEX(Sens_Types,MATCH($C25,Liste_Types,0)),"")) | J25: =IF($I25="▲ ENTRÉE",$U25,"") | K25: =IF($I25="▼ SORTIE",$U25,"") | L25: =$L24+N($J25)-N($K25) | T25: =IF($G25="","",IFERROR(INDEX(Taux_Devises,MATCH(IF($M25="",Devise_Base,$M25),Codes_Devises,0)),1)) | U25: =IF($G25="","",ROUND($G25*$T25,2)) | V25: =IF($B25="","",MONTH($B25)) | W25: =IF($B25="","",YEAR($B25))
... I3012: =IF($C3012="","",IFERROR(INDEX(Sens_Types,MATCH($C3012,Liste_Types,0)),"")) | J3012: =IF($I3012="▲ ENTRÉE",$U3012,"") | K3012: =IF($I3012="▼ SORTIE",$U3012,"") | L3012: =$L3011+N($J3012)-N($K3012) | T3012: =IF($G3012="","",IFERROR(INDEX(Taux_Devises,MATCH(IF($M3012="",Devise_Base,$M3012),Codes_Devises,0)),1)) | U3012: =IF($G3012="","",ROUND($G3012*$T3012,2)) | V3012: =IF($B3012="","",MONTH($B3012)) | W3012: =IF($B3012="","",YEAR($B3012))

Sheet Tableau de Bord
B1: TABLEAU DE BORD MENSUEL
B2: ="Suivi de "&Nom_Foyer&" • "&Mois_Suivi&" "&Annee_Travail&" • périmètre : "&Perimetre&" • montants en "&Devise_Base
B3: ⌂ ACCUEIL | D3: ① MES INFOS | F3: ② ESTIMATION | H3: ③ BUDGET SMART | J3: TABLEAU DE BORD | L3: BUDGET 12 MOIS
B4: PÉRIODE ANALYSÉE | D4: 2026 | E4: ◄ année | F4: mois ► | G4: Janvier | H4: =IFERROR(MATCH($G$4,Liste_Mois,0),1) | I4: ="Mise à jour au "&RIGHT("0"&DAY(TODAY()),2)&"/"&RIGHT("0"&MONTH(TODAY()),2)&"/"&YEAR(TODAY())&" • "&COUNT(J_Date)&" écritures enregistrées • Devise : "&Devise_Base&" ("&Symbole_Base&")"
B6: REVENUS DU MOIS | E6: DÉPENSES DU MOIS | H6: ÉPARGNE + INVESTI. | K6: SOLDE DU MOIS | N6: TAUX D'ÉPARGNE
B7: =INDEX(Calculs!$D$6:$O$17,Mois_Num,1) | E7: =INDEX(Calculs!$D$6:$O$17,Mois_Num,2) | H7: =INDEX(Calculs!$D$6:$O$17,Mois_Num,3)+INDEX(Calculs!$D$6:$O$17,Mois_Num,4) | K7: =INDEX(Calculs!$D$6:$O$17,Mois_Num,7) | N7: =INDEX(Calculs!$D$6:$O$17,Mois_Num,9)
B8: ="Prévu : "&FIXED(INDEX(Calculs!$D$6:$O$17,Mois_Num,12),0) | E8: ="Budget : "&FIXED(INDEX(Calculs!$D$6:$O$17,Mois_Num,10),0) | H8: ="Objectif : "&FIXED(Taux_Cible*INDEX(Calculs!$D$6:$O$17,Mois_Num,1),0) | K8: =IF(INDEX(Calculs!$D$6:$O$17,Mois_Num,7)>=0,"Excédent","Déficit à couvrir") | N8: ="Cible : "&ROUND(Taux_Cible*100,0)&" %"
B10: BUDGET CONSOMMÉ | E10: TRÉSORERIE CUMULÉE | H10: CHARGES FIXES DU MOIS | K10: RESTE À VIVRE | N10: DÉPENSE MOYENNE / JOUR
B11: =IFERROR(INDEX(Calculs!$D$6:$O$17,Mois_Num,2)/INDEX(Calculs!$D$6:$O$17,Mois_Num,10),0) | E11: =INDEX(Calculs!$D$6:$O$17,Mois_Num,8) | H11: =SUMIFS(J_Montant,J_Annee,Annee_Travail,J_Mois,Mois_Num,J_Nature,"Fixe",J_Type,"<>Revenu",J_Type,"<>Transfert",J_Module,Perimetre_Filtre,J_Statut,"<>Annulé",J_Statut,"<>Prévu") | K11: =INDEX(Calculs!$D$6:$O$17,Mois_Num,1)-SUMIFS(J_Montant,J_Annee,Annee_Travail,J_Mois,Mois_Num,J_Nature,"Fixe",J_Type,"<>Revenu",J_Type,"<>Transfert",J_Module,Perimetre_Filtre,J_Statut,"<>Annulé",J_Statut,"<>Prévu") | N11: =IFERROR(INDEX(Calculs!$D$6:$O$17,Mois_Num,2)/DAY(EOMONTH(DATE(Annee_Travail,Mois_Num,1),0)),0)
B12: ="Écart : "&FIXED(INDEX(Calculs!$D$6:$O$17,Mois_Num,11),0) | E12: ="Dont comptes : "&FIXED(Paramètres!$H$61,0) | H12: Loyer, abonnements, mensualités | K12: Revenus – charges fixes | N12: Sur le mois sélectionné
B14: RÉPARTITION DU MOIS SÉLECTIONNÉ
K15: Top 10 des dépenses du mois | M15: Montant | O15: Part
K16: =IF(Calculs!$C$183="","—",Calculs!$C$183) | M16: =Calculs!$D$183 | O16: =Calculs!$E$183
K17: =IF(Calculs!$C$184="","—",Calculs!$C$184) | M17: =Calculs!$D$184 | O17: =Calculs!$E$184
K18: =IF(Calculs!$C$185="","—",Calculs!$C$185) | M18: =Calculs!$D$185 | O18: =Calculs!$E$185
K19: =IF(Calculs!$C$186="","—",Calculs!$C$186) | M19: =Calculs!$D$186 | O19: =Calculs!$E$186
K20: =IF(Calculs!$C$187="","—",Calculs!$C$187) | M20: =Calculs!$D$187 | O20: =Calculs!$E$187
K21: =IF(Calculs!$C$188="","—",Calculs!$C$188) | M21: =Calculs!$D$188 | O21: =Calculs!$E$188
K22: =IF(Calculs!$C$189="","—",Calculs!$C$189) | M22: =Calculs!$D$189 | O22: =Calculs!$E$189
K23: =IF(Calculs!$C$190="","—",Calculs!$C$190) | M23: =Calculs!$D$190 | O23: =Calculs!$E$190
K24: =IF(Calculs!$C$191="","—",Calculs!$C$191) | M24: =Calculs!$D$191 | O24: =Calculs!$E$191
K25: =IF(Calculs!$C$192="","—",Calculs!$C$192) | M25: =Calculs!$D$192 | O25: =Calculs!$E$192
B28: PRÉVU vs RÉALISÉ — MOIS SÉLECTIONNÉ
C29: Module | D29: Prévu | E29: Réalisé | F29: Écart | G29: % consommé | H29: Statut
C30: Général | D30: =Calculs!$C$301 | E30: =Calculs!$D$301 | F30: =Calculs!$E$301 | G30: =IFERROR($E30/$D30,0) | H30: =IF($D30=0,"Non budgété",IF($G30>1,"⚠ Dépassement",IF($G30>Seuil_Alerte,"Vigilance","✓ Sous contrôle")))
C31: Mariage | D31: =Calculs!$C$302 | E31: =Calculs!$D$302 | F31: =Calculs!$E$302 | G31: =IFERROR($E31/$D31,0) | H31: =IF($D31=0,"Non budgété",IF($G31>1,"⚠ Dépassement",IF($G31>Seuil_Alerte,"Vigilance","✓ Sous contrôle")))
C32: Immobilier | D32: =Calculs!$C$303 | E32: =Calculs!$D$303 | F32: =Calculs!$E$303 | G32: =IFERROR($E32/$D32,0) | H32: =IF($D32=0,"Non budgété",IF($G32>1,"⚠ Dépassement",IF($G32>Seuil_Alerte,"Vigilance","✓ Sous contrôle")))
C33: Business | D33: =Calculs!$C$304 | E33: =Calculs!$D$304 | F33: =Calculs!$E$304 | G33: =IFERROR($E33/$D33,0) | H33: =IF($D33=0,"Non budgété",IF($G33>1,"⚠ Dépassement",IF($G33>Seuil_Alerte,"Vigilance","✓ Sous contrôle")))
C34: TOTAL | D34: =SUM(D30:D33) | E34: =SUM(E30:E33) | F34: =SUM(F30:F33) | G34: =IFERROR(E34/D34,0)
B38: DÎME DU MOIS
C39: Revenus soumis à la dîme | F39: =INDEX(Calculs!$C$308:$C$319,Mois_Num)
C40: Dîme due | F40: =INDEX(Calculs!$D$308:$D$319,Mois_Num)
C41: Déjà versée | F41: =INDEX(Calculs!$E$308:$E$319,Mois_Num)
C42: Reste à verser | F42: =INDEX(Calculs!$F$308:$F$319,Mois_Num)
C43: =IF(Dime_Active<>"Oui","Dîme désactivée dans Paramètres.",IF($F$40=0,"Aucun revenu soumis ce mois-ci.",IF($F$42<=0,"✓ Dîme du mois entièrement versée.","Il reste "&FIXED($F$42,0)&" "&Symbole_Base&" à verser.")))
B46: ALERTES & SIGNAUX AUTOMATIQUES
B47: =IF(INDEX(Calculs!$D$6:$O$17,Mois_Num,7)<0,"🔴 Le mois est déficitaire de "&FIXED(ABS(INDEX(Calculs!$D$6:$O$17,Mois_Num,7)),0)&" "&Symbole_Base&". Réduisez les postes variables ou puisez dans vos réserves.","🟢 Le mois est excédentaire.")
B48: =IF(INDEX(Calculs!$D$6:$O$17,Mois_Num,9)<Taux_Cible,"🟠 Taux d'épargne de "&ROUND(INDEX(Calculs!$D$6:$O$17,Mois_Num,9)*100,1)&" %"&" contre "&ROUND(Taux_Cible*100,0)&" %"&" visé.","🟢 Objectif d'épargne atteint.")
B49: =IF(AND(INDEX(Calculs!$D$6:$O$17,Mois_Num,10)>0,INDEX(Calculs!$D$6:$O$17,Mois_Num,2)>INDEX(Calculs!$D$6:$O$17,Mois_Num,10)),"🔴 Budget de dépenses dépassé de "&FIXED(INDEX(Calculs!$D$6:$O$17,Mois_Num,2)-INDEX(Calculs!$D$6:$O$17,Mois_Num,10),0)&" "&Symbole_Base&".",IF(INDEX(Calculs!$D$6:$O$17,Mois_Num,10)=0,"⚪ Aucun budget saisi pour ce mois dans le Estimation annuelle.","🟢 Dépenses contenues dans le budget."))
B50: =IF(COUNTIFS(Récurrents!$J$8:$J$57,"Oui",Récurrents!$H$8:$H$57,"<"&TODAY())>0,"🔴 "&COUNTIFS(Récurrents!$J$8:$J$57,"Oui",Récurrents!$H$8:$H$57,"<"&TODAY())&" échéance(s) récurrente(s) en retard.","🟢 Aucune échéance récurrente en retard.")
...

Sheet Budget 12 Mois
B1: BUDGET 12 MOIS — ENTRÉES & SORTIES
B2: ="Année "&Annee_Travail&" • "&Nom_Foyer&" • Prévu issu du Estimation annuelle, Réel issu du Journal • montants en "&Devise_Base
B3: ⌂ ACCUEIL | G3: ① MES INFOS | L3: ② ESTIMATION | Q3: ③ BUDGET SMART | V3: TABLEAU DE BORD | AA3: BUDGET 12 MOIS
B5: Cette feuille ne se remplit pas à la main. Colonne « Prévu » = ce que vous avez inscrit dans le Estimation annuelle. Colonne « Réel » = ce que vous avez enregistré dans le Journal. Changez l'année en haut du Tableau de bord.
B8: POSTE | D8: Janvier | F8: Février | H8: Mars | J8: Avril | L8: Mai | N8: Juin | P8: Juillet | R8: Août | T8: Septembre | V8: Octobre | X8: Novembre | Z8: Décembre | AB8: TOTAL DE L'ANNÉE
D9: Prévu | E9: Réel | F9: Prévu | G9: Réel | H9: Prévu | I9: Réel | J9: Prévu | K9: Réel | L9: Prévu | M9: Réel | N9: Prévu | O9: Réel | P9: Prévu | Q9: Réel | R9: Prévu | S9: Réel | T9: Prévu | U9: Réel | V9: Prévu | W9: Réel | X9: Prévu | Y9: Réel | Z9: Prévu | AA9: Réel | AB9: Prévu | AC9: Réel | AD9: Écart | AE9: % consommé
B10: A ▸ ENTRÉES — REVENUS
B11: 1 | C11: Salaire | D11: =IF($C11="",0,SUMIFS(P_M1,P_Annee,Annee_Travail,P_Cat,$C11,P_Type,"Revenu")) | E11: =IF($C11="",0,SUMIFS(J_Montant,J_Annee,Annee_Travail,J_Mois,1,J_Cat,$C11,J_Type,"Revenu",J_Statut,"<>Annulé",J_Statut,"<>Prévu")) | F11: =IF($C11="",0,SUMIFS(P_M2,P_Annee,Annee_Travail,P_Cat,$C11,P_Type,"Revenu")) | G11: =IF($C11="",0,SUMIFS(J_Montant,J_Annee,Annee_Travail,J_Mois,2,J_Cat,$C11,J_Type,"Revenu",J_Statut,"<>Annulé",J_Statut,"<>Prévu")) | H11: =IF($C11="",0,SUMIFS(P_M3,P_Annee,Annee_Travail,P_Cat,$C11,P_Type,"Revenu")) | I11: =IF($C11="",0,SUMIFS(J_Montant,J_Annee,Annee_Travail,J_Mois,3,J_Cat,$C11,J_Type,"Revenu",J_Statut,"<>Annulé",J_Statut,"<>Prévu")) | J11: =IF($C11="",0,SUMIFS(P_M4,P_Annee,Annee_Travail,P_Cat,$C11,P_Type,"Revenu")) | K11: =IF($C11="",0,SUMIFS(J_Montant,J_Annee,Annee_Travail,J_Mois,4,J_Cat,$C11,J_Type,"Revenu",J_Statut,"<>Annulé",J_Statut,"<>Prévu")) | L11: =IF($C11="",0,SUMIFS(P_M5,P_Annee,Annee_Travail,P_Cat,$C11,P_Type,"Revenu")) | M11: =IF($C11="",0,SUMIFS(J_Montant,J_Annee,Annee_Travail,J_Mois,5,J_Cat,$C11,J_Type,"Revenu",J_Statut,"<>Annulé",J_Statut,"<>Prévu")) | N11: =IF($C11="",0,SUMIFS(P_M6,P_Annee,Annee_Travail,P_Cat,$C11,P_Type,"Revenu")) | O11: =IF($C11="",0,SUMIFS(J_Montant,J_Annee,Annee_Travail,J_Mois,6,J_Cat,$C11,J_Type,"Revenu",J_Statut,"<>Annulé",J_Statut,"<>Prévu")) | P11: =IF($C11="",0,SUMIFS(P_M7,P_Annee,Annee_Travail,P_Cat,$C11,P_Type,"Revenu")) | Q11: =IF($C11="",0,SUMIFS(J_Montant,J_Annee,Annee_Travail,J_Mois,7,J_Cat,$C11,J_Type,"Revenu",J_Statut,"<>Annulé",J_Statut,"<>Prévu")) | R11: =IF($C11="",0,SUMIFS(P_M8,P_Annee,Annee_Travail,P_Cat,$C11,P_Type,"Revenu")) | S11: =IF($C11="",0,SUMIFS(J_Montant,J_Annee,Annee_Travail,J_Mois,8,J_Cat,$C11,J_Type,"Revenu",J_Statut,"<>Annulé",J_Statut,"<>Prévu")) | T11: =IF($C11="",0,SUMIFS(P_M9,P_Annee,Annee_Travail,P_Cat,$C11,P_Type,"Revenu")) | U11: =IF($C11="",0,SUMIFS(J_Montant,J_Annee,Annee_Travail,J_Mois,9,J_Cat,$C11,J_Type,"Revenu",J_Statut,"<>Annulé",J_Statut,"<>Prévu")) | V11: =IF($C11="",0,SUMIFS(P_M10,P_Annee,Annee_Travail,P_Cat,$C11,P_Type,"Revenu")) | W11: =IF($C11="",0,SUMIFS(J_Montant,J_Annee,Annee_Travail,J_Mois,10,J_Cat,$C11,J_Type,"Revenu",J_Statut,"<>Annulé",J_Statut,"<>Prévu")) | X11: =IF($C11="",0,SUMIFS(P_M11,P_Annee,Annee_Travail,P_Cat,$C11,P_Type,"Revenu")) | Y11: =IF($C11="",0,SUMIFS(J_Montant,J_Annee,Annee_Travail,J_Mois,11,J_Cat,$C11,J_Type,"Revenu",J_Statut,"<>Annulé",J_Statut,"<>Prévu")) | Z11: =IF($C11="",0,SUMIFS(P_M12,P_Annee,Annee_Travail,P_Cat,$C11,P_Type,"Revenu")) | AA11: =IF($C11="",0,SUMIFS(J_Montant,J_Annee,Annee_Travail,J_Mois,12,J_Cat,$C11,J_Type,"Revenu",J_Statut,"<>Annulé",J_Statut,"<>Prévu")) | AB11: =D11+F11+H11+J11+L11+N11+P11+R11+T11+V11+X11+Z11 | AC11: =E11+G11+I11+K11+M11+O11+Q11+S11+U11+W11+Y11+AA11 | AD11: =$AC11-$AB11 | AE11: =IFERROR($AC11/$AB11,0)
B12: 2 | C12: Prime / 13e mois | D12: =IF($C12="",0,SUMIFS(P_M1,P_Annee,Annee_Travail,P_Cat,$C12,P_Type,"Revenu")) | E12: =IF($C12="",0,SUMIFS(J_Montant,J_Annee,Annee_Travail,J_Mois,1,J_Cat,$C12,J_Type,"Revenu",J_Statut,"<>Annulé",J_Statut,"<>Prévu")) | F12: =IF($C12="",0,SUMIFS(P_M2,P_Annee,Annee_Travail,P_Cat,$C12,P_Type,"Revenu")) | G12: =IF($C12="",0,SUMIFS(J_Montant,J_Annee,Annee_Travail,J_Mois,2,J_Cat,$C12,J_Type,"Revenu",J_Statut,"<>Annulé",J_Statut,"<>Prévu")) | H12: =IF($C12="",0,SUMIFS(P_M3,P_Annee,Annee_Travail,P_Cat,$C12,P_Type,"Revenu")) | I12: =IF($C12="",0,SUMIFS(J_Montant,J_Annee,Annee_Travail,J_Mois,3,J_Cat,$C12,J_Type,"Revenu",J_Statut,"<>Annulé",J_Statut,"<>Prévu")) | J12: =IF($C12="",0,SUMIFS(P_M4,P_Annee,Annee_Travail,P_Cat,$C12,P_Type,"Revenu")) | K12: =IF($C12="",0,SUMIFS(J_Montant,J_Annee,Annee_Travail,J_Mois,4,J_Cat,$C12,J_Type,"Revenu",J_Statut,"<>Annulé",J_Statut,"<>Prévu")) | L12: =IF($C12="",0,SUMIFS(P_M5,P_Annee,Annee_Travail,P_Cat,$C12,P_Type,"Revenu")) | M12: =IF($C12="",0,SUMIFS(J_Montant,J_Annee,Annee_Travail,J_Mois,5,J_Cat,$C12,J_Type,"Revenu",J_Statut,"<>Annulé",J_Statut,"<>Prévu")) | N12: =IF($C12="",0,SUMIFS(P_M6,P_Annee,Annee_Travail,P_Cat,$C12,P_Type,"Revenu")) | O12: =IF($C12="",0,SUMIFS(J_Montant,J_Annee,Annee_Travail,J_Mois,6,J_Cat,$C12,J_Type,"Revenu",J_Statut,"<>Annulé",J_Statut,"<>Prévu")) | P12: =IF($C12="",0,SUMIFS(P_M7,P_Annee,Annee_Travail,P_Cat,$C12,P_Type,"Revenu")) | Q12: =IF($C12="",0,SUMIFS(J_Montant,J_Annee,Annee_Travail,J_Mois,7,J_Cat,$C12,J_Type,"Revenu",J_Statut,"<>Annulé",J_Statut,"<>Prévu")) | R12: =IF($C12="",0,SUMIFS(P_M8,P_Annee,Annee_Travail,P_Cat,$C12,P_Type,"Revenu")) | S12: =IF($C12="",0,SUMIFS(J_Montant,J_Annee,Annee_Travail,J_Mois,8,J_Cat,$C12,J_Type,"Revenu",J_Statut,"<>Annulé",J_Statut,"<>Prévu")) | T12: =IF($C12="",0,SUMIFS(P_M9,P_Annee,Annee_Travail,P_Cat,$C12,P_Type,"Revenu")) | U12: =IF($C12="",0,SUMIFS(J_Montant,J_Annee,Annee_Travail,J_Mois,9,J_Cat,$C12,J_Type,"Revenu",J_Statut,"<>Annulé",J_Statut,"<>Prévu")) | V12: =IF($C12="",0,SUMIFS(P_M10,P_Annee,Annee_Travail,P_Cat,$C12,P_Type,"Revenu")) | W12: =IF($C12="",0,SUMIFS(J_Montant,J_Annee,Annee_Travail,J_Mois,10,J_Cat,$C12,J_Type,"Revenu",J_Statut,"<>Annulé",J_Statut,"<>Prévu")) | X12: =IF($C12="",0,SUMIFS(P_M11,P_Annee,Annee_Travail,P_Cat,$C12,P_Type,"Revenu")) | Y12: =IF($C12="",0,SUMIFS(J_Montant,J_Annee,Annee_Travail,J_Mois,11,J_Cat,$C12,J_Type,"Revenu",J_Statut,"<>Annulé",J_Statut,"<>Prévu")) | Z12: =IF($C12="",0,SUMIFS(P_M12,P_Annee,Annee_Travail,P_Cat,$C12,P_Type,"Revenu")) | AA12: =IF($C12="",0,SUMIFS(J_Montant,J_Annee,Annee_Travail,J_Mois,12,J_Cat,$C12,J_Type,"Revenu",J_Statut,"<>Annulé",J_Statut,"<>Prévu")) | AB12: =D12+F12+H12+J12+L12+N12+P12+R12+T12+V12+X12+Z12 | AC12: =E12+G12+I12+K12+M12+O12+Q12+S12+U12+W12+Y12+AA12 | AD12: =$AC12-$AB12 | AE12: =IFERROR($AC12/$AB12,0)
B13: 3 | C13: Freelance / Consulting | D13: =IF($C13="",0,SUMIFS(P_M1,P_Annee,Annee_Travail,P_Cat,$C13,P_Type,"Revenu")) | E13: =IF($C13="",0,SUMIFS(J_Montant,J_Annee,Annee_Travail,J_Mois,1,J_Cat,$C13,J_Type,"Revenu",J_Statut,"<>Annulé",J_Statut,"<>Prévu")) | F13: =IF($C13="",0,SUMIFS(P_M2,P_Annee,Annee_Travail,P_Cat,$C13,P_Type,"Revenu")) | G13: =IF($C13="",0,SUMIFS(J_Montant,J_Annee,Annee_Travail,J_Mois,2,J_Cat,$C13,J_Type,"Revenu",J_Statut,"<>Annulé",J_Statut,"<>Prévu")) | H13: =IF($C13="",0,SUMIFS(P_M3,P_Annee,Annee_Travail,P_Cat,$C13,P_Type,"Revenu")) | I13: =IF($C13="",0,SUMIFS(J_Montant,J_Annee,Annee_Travail,J_Mois,3,J_Cat,$C13,J_Type,"Revenu",J_Statut,"<>Annulé",J_Statut,"<>Prévu")) | J13: =IF($C13="",0,SUMIFS(P_M4,P_Annee,Annee_Travail,P_Cat,$C13,P_Type,"Revenu")) | K13: =IF($C13="",0,SUMIFS(J_Montant,J_Annee,Annee_Travail,J_Mois,4,J_Cat,$C13,J_Type,"Revenu",J_Statut,"<>Annulé",J_Statut,"<>Prévu")) | L13: =IF($C13="",0,SUMIFS(P_M5,P_Annee,Annee_Travail,P_Cat,$C13,P_Type,"Revenu")) | M13: =IF($C13="",0,SUMIFS(J_Montant,J_Annee,Annee_Travail,J_Mois,5,J_Cat,$C13,J_Type,"Revenu",J_Statut,"<>Annulé",J_Statut,"<>Prévu")) | N13: =IF($C13="",0,SUMIFS(P_M6,P_Annee,Annee_Travail,P_Cat,$C13,P_Type,"Revenu")) | O13: =IF($C13="",0,SUMIFS(J_Montant,J_Annee,Annee_Travail,J_Mois,6,J_Cat,$C13,J_Type,"Revenu",J_Statut,"<>Annulé",J_Statut,"<>Prévu")) | P13: =IF($C13="",0,SUMIFS(P_M7,P_Annee,Annee_Travail,P_Cat,$C13,P_Type,"Revenu")) | Q13: =IF($C13="",0,SUMIFS(J_Montant,J_Annee,Annee_Travail,J_Mois,7,J_Cat,$C13,J_Type,"Revenu",J_Statut,"<>Annulé",J_Statut,"<>Prévu")) | R13: =IF($C13="",0,SUMIFS(P_M8,P_Annee,Annee_Travail,P_Cat,$C13,P_Type,"Revenu")) | S13: =IF($C13="",0,SUMIFS(J_Montant,J_Annee,Annee_Travail,J_Mois,8,J_Cat,$C13,J_Type,"Revenu",J_Statut,"<>Annulé",J_Statut,"<>Prévu")) | T13: =IF($C13="",0,SUMIFS(P_M9,P_Annee,Annee_Travail,P_Cat,$C13,P_Type,"Revenu")) | U13: =IF($C13="",0,SUMIFS(J_Montant,J_Annee,Annee_Travail,J_Mois,9,J_Cat,$C13,J_Type,"Revenu",J_Statut,"<>Annulé",J_Statut,"<>Prévu")) | V13: =IF($C13="",0,SUMIFS(P_M10,P_Annee,Annee_Travail,P_Cat,$C13,P_Type,"Revenu")) | W13: =IF($C13="",0,SUMIFS(J_Montant,J_Annee,Annee_Travail,J_Mois,10,J_Cat,$C13,J_Type,"Revenu",J_Statut,"<>Annulé",J_Statut,"<>Prévu")) | X13: =IF($C13="",0,SUMIFS(P_M11,P_Annee,Annee_Travail,P_Cat,$C13,P_Type,"Revenu")) | Y13: =IF($C13="",0,SUMIFS(J_Montant,J_Annee,Annee_Travail,J_Mois,11,J_Cat,$C13,J_Type,"Revenu",J_Statut,"<>Annulé",J_Statut,"<>Prévu")) | Z13: =IF($C13="",0,SUMIFS(P_M12,P_Annee,Annee_Travail,P_Cat,$C13,P_Type,"Revenu")) | AA13: =IF($C13="",0,SUMIFS(J_Montant,J_Annee,Annee_Travail,J_Mois,12,J_Cat,$C13,J_Type,"Revenu",J_Statut,"<>Annulé",J_Statut,"<>Prévu")) | AB13: =D13+F13+H13+J13+L13+N13+P13+R13+T13+V13+X13+Z13 | AC13: =E13+G13+I13+K13+M13+O13+Q13+S13+U13+W13+Y13+AA13 | AD13: =$AC13-$AB13 | AE13: =IFERROR($AC13/$AB13,0)
B14: 4 | C14: Commerce / Ventes | D14: =IF($C14="",0,SUMIFS(P_M1,P_Annee,Annee_Travail,P_Cat,$C14,P_Type,"Revenu")) | E14: =IF($C14="",0,SUMIFS(J_Montant,J_Annee,Annee_Travail,J_Mois,1,J_Cat,$C14,J_Type,"Revenu",J_Statut,"<>Annulé",J_Statut,"<>Prévu")) | F14: =IF($C14="",0,SUMIFS(P_M2,P_Annee,Annee_Travail,P_Cat,$C14,P_Type,"Revenu")) | G14: =IF($C14="",0,SUMIFS(J_Montant,J_Annee,Annee_Travail,J_Mois,2,J_Cat,$C14,J_Type,"Revenu",J_Statut,"<>Annulé",J_Statut,"<>Prévu")) | H14: =IF($C14="",0,SUMIFS(P_M3,P_Annee,Annee_Travail,P_Cat,$C14,P_Type,"Revenu")) | I14: =IF($C14="",0,SUMIFS(J_Montant,J_Annee,Annee_Travail,J_Mois,3,J_Cat,$C14,J_Type,"Revenu",J_Statut,"<>Annulé",J_Statut,"<>Prévu")) | J14: =IF($C14="",0,SUMIFS(P_M4,P_Annee,Annee_Travail,P_Cat,$C14,P_Type,"Revenu")) | K14: =IF($C14="",0,SUMIFS(J_Montant,J_Annee,Annee_Travail,J_Mois,4,J_Cat,$C14,J_Type,"Revenu",J_Statut,"<>Annulé",J_Statut,"<>Prévu")) | L14: =IF($C14="",0,SUMIFS(P_M5,P_Annee,Annee_Travail,P_Cat,$C14,P_Type,"Revenu")) | M14: =IF($C14="",0,SUMIFS(J_Montant,J_Annee,Annee_Travail,J_Mois,5,J_Cat,$C14,J_Type,"Revenu",J_Statut,"<>Annulé",J_Statut,"<>Prévu")) | N14: =IF($C14="",0,SUMIFS(P_M6,P_Annee,Annee_Travail,P_Cat,$C14,P_Type,"Revenu")) | O14: =IF($C14="",0,SUMIFS(J_Montant,J_Annee,Annee_Travail,J_Mois,6,J_Cat,$C14,J_Type,"Revenu",J_Statut,"<>Annulé",J_Statut,"<>Prévu")) | P14: =IF($C14="",0,SUMIFS(P_M7,P_Annee,Annee_Travail,P_Cat,$C14,P_Type,"Revenu")) | Q14: =IF($C14="",0,SUMIFS(J_Montant,J_Annee,Annee_Travail,J_Mois,7,J_Cat,$C14,J_Type,"Revenu",J_Statut,"<>Annulé",J_Statut,"<>Prévu")) | R14: =IF($C14="",0,SUMIFS(P_M8,P_Annee,Annee_Travail,P_Cat,$C14,P_Type,"Revenu")) | S14: =IF($C14="",0,SUMIFS(J_Montant,J_Annee,Annee_Travail,J_Mois,8,J_Cat,$C14,J_Type,"Revenu",J_Statut,"<>Annulé",J_Statut,"<>Prévu")) | T14: =IF($C14="",0,SUMIFS(P_M9,P_Annee,Annee_Travail,P_Cat,$C14,P_Type,"Revenu")) | U14: =IF($C14="",0,SUMIFS(J_Montant,J_Annee,Annee_Travail,J_Mois,9,J_Cat,$C14,J_Type,"Revenu",J_Statut,"<>Annulé",J_Statut,"<>Prévu")) | V14: =IF($C14="",0,SUMIFS(P_M10,P_Annee,Annee_Travail,P_Cat,$C14,P_Type,"Revenu")) | W14: =IF($C14="",0,SUMIFS(J_Montant,J_Annee,Annee_Travail,J_Mois,10,J_Cat,$C14,J_Type,"Revenu",J_Statut,"<>Annulé",J_Statut,"<>Prévu")) | X14: =IF($C14="",0,SUMIFS(P_M11,P_Annee,Annee_Travail,P_Cat,$C14,P_Type,"Revenu")) | Y14: =IF($C14="",0,SUMIFS(J_Montant,J_Annee,Annee_Travail,J_Mois,11,J_Cat,$C14,J_Type,"Revenu",J_Statut,"<>Annulé",J_Statut,"<>Prévu")) | Z14: =IF($C14="",0,SUMIFS(P_M12,P_Annee,Annee_Travail,P_Cat,$C14,P_Type,"Revenu")) | AA14: =IF($C14="",0,SUMIFS(J_Montant,J_Annee,Annee_Travail,J_Mois,12,J_Cat,$C14,J_Type,"Revenu",J_Statut,"<>Annulé",J_Statut,"<>Prévu")) | AB14: =D14+F14+H14+J14+L14+N14+P14+R14+T14+V14+X14+Z14 | AC14: =E14+G14+I14+K14+M14+O14+Q14+S14+U14+W14+Y14+AA14 | AD14: =$AC14-$AB14 | AE14: =IFERROR($AC14/$AB14,0)
B15: 5 | C15: Loyers perçus | D15: =IF($C15="",0,SUMIFS(P_M1,P_Annee,Annee_Travail,P_Cat,$C15,P_Type,"Revenu")) | E15: =IF($C15="",0,SUMIFS(J_Montant,J_Annee,Annee_Travail,J_Mois,1,J_Cat,$C15,J_Type,"Revenu",J_Statut,"<>Annulé",J_Statut,"<>Prévu")) | F15: =IF($C15="",0,SUMIFS(P_M2,P_Annee,Annee_Travail,P_Cat,$C15,P_Type,"Revenu")) | G15: =IF($C15="",0,SUMIFS(J_Montant,J_Annee,Annee_Travail,J_Mois,2,J_Cat,$C15,J_Type,"Revenu",J_Statut,"<>Annulé",J_Statut,"<>Prévu")) | H15: =IF($C15="",0,SUMIFS(P_M3,P_Annee,Annee_Travail,P_Cat,$C15,P_Type,"Revenu")) | I15: =IF($C15="",0,SUMIFS(J_Montant,J_Annee,Annee_Travail,J_Mois,3,J_Cat,$C15,J_Type,"Revenu",J_Statut,"<>Annulé",J_Statut,"<>Prévu")) | J15: =IF($C15="",0,SUMIFS(P_M4,P_Annee,Annee_Travail,P_Cat,$C15,P_Type,"Revenu")) | K15: =IF($C15="",0,SUMIFS(J_Montant,J_Annee,Annee_Travail,J_Mois,4,J_Cat,$C15,J_Type,"Revenu",J_Statut,"<>Annulé",J_Statut,"<>Prévu")) | L15: =IF($C15="",0,SUMIFS(P_M5,P_Annee,Annee_Travail,P_Cat,$C15,P_Type,"Revenu")) | M15: =IF($C15="",0,SUMIFS(J_Montant,J_Annee,Annee_Travail,J_Mois,5,J_Cat,$C15,J_Type,"Revenu",J_Statut,"<>Annulé",J_Statut,"<>Prévu")) | N15: =IF($C15="",0,SUMIFS(P_M6,P_Annee,Annee_Travail,P_Cat,$C15,P_Type,"Revenu")) | O15: =IF($C15="",0,SUMIFS(J_Montant,J_Annee,Annee_Travail,J_Mois,6,J_Cat,$C15,J_Type,"Revenu",J_Statut,"<>Annulé",J_Statut,"<>Prévu")) | P15: =IF($C15="",0,SUMIFS(P_M7,P_Annee,Annee_Travail,P_Cat,$C15,P_Type,"Revenu")) | Q15: =IF($C15="",0,SUMIFS(J_Montant,J_Annee,Annee_Travail,J_Mois,7,J_Cat,$C15,J_Type,"Revenu",J_Statut,"<>Annulé",J_Statut,"<>Prévu")) | R15: =IF($C15="",0,SUMIFS(P_M8,P_Annee,Annee_Travail,P_Cat,$C15,P_Type,"Revenu")) | S15: =IF($C15="",0,SUMIFS(J_Montant,J_Annee,Annee_Travail,J_Mois,8,J_Cat,$C15,J_Type,"Revenu",J_Statut,"<>Annulé",J_Statut,"<>Prévu")) | T15: =IF($C15="",0,SUMIFS(P_M9,P_Annee,Annee_Travail,P_Cat,$C15,P_Type,"Revenu")) | U15: =IF($C15="",0,SUMIFS(J_Montant,J_Annee,Annee_Travail,J_Mois,9,J_Cat,$C15,J_Type,"Revenu",J_Statut,"<>Annulé",J_Statut,"<>Prévu")) | V15: =IF($C15="",0,SUMIFS(P_M10,P_Annee,Annee_Travail,P_Cat,$C15,P_Type,"Revenu")) | W15: =IF($C15="",0,SUMIFS(J_Montant,J_Annee,Annee_Travail,J_Mois,10,J_Cat,$C15,J_Type,"Revenu",J_Statut,"<>Annulé",J_Statut,"<>Prévu")) | X15: =IF($C15="",0,SUMIFS(P_M11,P_Annee,Annee_Travail,P_Cat,$C15,P_Type,"Revenu")) | Y15: =IF($C15="",0,SUMIFS(J_Montant,J_Annee,Annee_Travail,J_Mois,11,J_Cat,$C15,J_Type,"Revenu",J_Statut,"<>Annulé",J_Statut,"<>Prévu")) | Z15: =IF($C15="",0,SUMIFS(P_M12,P_Annee,Annee_Travail,P_Cat,$C15,P_Type,"Revenu")) | AA15: =IF($C15="",0,SUMIFS(J_Montant,J_Annee,Annee_Travail,J_Mois,12,J_Cat,$C15,J_Type,"Revenu",J_Statut,"<>Annulé",J_Statut,"<>Prévu")) | AB15: =D15+F15+H15+J15+L15+N15+P15+R15+T15+V15+X15+Z15 | AC15: =E15+G15+I15+K15+M15+O15+Q15+S15+U15+W15+Y15+AA15 | AD15: =$AC15-$AB15 | AE15: =IFERROR($AC15/$AB15,0)
B16: 6 | C16: Dividendes | D16: =IF($C16="",0,SUMIFS(P_M1,P_Annee,Annee_Travail,P_Cat,$C16,P_Type,"Revenu")) | E16: =IF($C16="",0,SUMIFS(J_Montant,J_Annee,Annee_Travail,J_Mois,1,J_Cat,$C16,J_Type,"Revenu",J_Statut,"<>Annulé",J_Statut,"<>Prévu")) | F16: =IF($C16="",0,SUMIFS(P_M2,P_Annee,Annee_Travail,P_Cat,$C16,P_Type,"Revenu")) | G16: =IF($C16="",0,SUMIFS(J_Montant,J_Annee,Annee_Travail,J_Mois,2,J_Cat,$C16,J_Type,"Revenu",J_Statut,"<>Annulé",J_Statut,"<>Prévu")) | H16: =IF($C16="",0,SUMIFS(P_M3,P_Annee,Annee_Travail,P_Cat,$C16,P_Type,"Revenu")) | I16: =IF($C16="",0,SUMIFS(J_Montant,J_Annee,Annee_Travail,J_Mois,3,J_Cat,$C16,J_Type,"Revenu",J_Statut,"<>Annulé",J_Statut,"<>Prévu")) | J16: =IF($C16="",0,SUMIFS(P_M4,P_Annee,Annee_Travail,P_Cat,$C16,P_Type,"Revenu")) | K16: =IF($C16="",0,SUMIFS(J_Montant,J_Annee,Annee_Travail,J_Mois,4,J_Cat,$C16,J_Type,"Revenu",J_Statut,"<>Annulé",J_Statut,"<>Prévu")) | L16: =IF($C16="",0,SUMIFS(P_M5,P_Annee,Annee_Travail,P_Cat,$C16,P_Type,"Revenu")) | M16: =IF($C16="",0,SUMIFS(J_Montant,J_Annee,Annee_Travail,J_Mois,5,J_Cat,$C16,J_Type,"Revenu",J_Statut,"<>Annulé",J_Statut,"<>Prévu")) | N16: =IF($C16="",0,SUMIFS(P_M6,P_Annee,Annee_Travail,P_Cat,$C16,P_Type,"Revenu")) | O16: =IF($C16="",0,SUMIFS(J_Montant,J_Annee,Annee_Travail,J_Mois,6,J_Cat,$C16,J_Type,"Revenu",J_Statut,"<>Annulé",J_Statut,"<>Prévu")) | P16: =IF($C16="",0,SUMIFS(P_M7,P_Annee,Annee_Travail,P_Cat,$C16,P_Type,"Revenu")) | Q16: =IF($C16="",0,SUMIFS(J_Montant,J_Annee,Annee_Travail,J_Mois,7,J_Cat,$C16,J_Type,"Revenu",J_Statut,"<>Annulé",J_Statut,"<>Prévu")) | R16: =IF($C16="",0,SUMIFS(P_M8,P_Annee,Annee_Travail,P_Cat,$C16,P_Type,"Revenu")) | S16: =IF($C16="",0,SUMIFS(J_Montant,J_Annee,Annee_Travail,J_Mois,8,J_Cat,$C16,J_Type,"Revenu",J_Statut,"<>Annulé",J_Statut,"<>Prévu")) | T16: =IF($C16="",0,SUMIFS(P_M9,P_Annee,Annee_Travail,P_Cat,$C16,P_Type,"Revenu")) | U16: =IF($C16="",0,SUMIFS(J_Montant,J_Annee,Annee_Travail,J_Mois,9,J_Cat,$C16,J_Type,"Revenu",J_Statut,"<>Annulé",J_Statut,"<>Prévu")) | V16: =IF($C16="",0,SUMIFS(P_M10,P_Annee,Annee_Travail,P_Cat,$C16,P_Type,"Revenu")) | W16: =IF($C16="",0,SUMIFS(J_Montant,J_Annee,Annee_Travail,J_Mois,10,J_Cat,$C16,J_Type,"Revenu",J_Statut,"<>Annulé",J_Statut,"<>Prévu")) | X16: =IF($C16="",0,SUMIFS(P_M11,P_Annee,Annee_Travail,P_Cat,$C16,P_Type,"Revenu")) | Y16: =IF($C16="",0,SUMIFS(J_Montant,J_Annee,Annee_Travail,J_Mois,11,J_Cat,$C16,J_Type,"Revenu",J_Statut,"<>Annulé",J_Statut,"<>Prévu")) | Z16: =IF($C16="",0,SUMIFS(P_M12,P_Annee,Annee_Travail,P_Cat,$C16,P_Type,"Revenu")) | AA16: =IF($C16="",0,SUMIFS(J_Montant,J_Annee,Annee_Travail,J_Mois,12,J_Cat,$C16,J_Type,"Revenu",J_Statut,"<>Annulé",J_Statut,"<>Prévu")) | AB16: =D16+F16+H16+J16+L16+N16+P16+R16+T16+V16+X16+Z16 | AC16: =E16+G16+I16+K16+M16+O16+Q16+S16+U16+W16+Y16+AA16 | AD16: =$AC16-$AB16 | AE16: =IFERROR($AC16/$AB16,0)
B17: 7 | C17: Intérêts perçus | D17: =IF($C17="",0,SUMIFS(P_M1,P_Annee,Annee_Travail,P_Cat,$C17,P_Type,"Revenu")) | E17: =IF($C17="",0,SUMIFS(J_Montant,J_Annee,Annee_Travail,J_Mois,1,J_Cat,$C17,J_Type,"Revenu",J_Statut,"<>Annulé",J_Statut,"<>Prévu")) | F17: =IF($C17="",0,SUMIFS(P_M2,P_Annee,Annee_Travail,P_Cat,$C17,P_Type,"Revenu")) | G17: =IF($C17="",0,SUMIFS(J_Montant,J_Annee,Annee_Travail,J_Mois,2,J_Cat,$C17,J_Type,"Revenu",J_Statut,"<>Annulé",J_Statut,"<>Prévu")) | H17: =IF($C17="",0,SUMIFS(P_M3,P_Annee,Annee_Travail,P_Cat,$C17,P_Type,"Revenu")) | I17: =IF($C17="",0,SUMIFS(J_Montant,J_Annee,Annee_Travail,J_Mois,3,J_Cat,$C17,J_Type,"Revenu",J_Statut,"<>Annulé",J_Statut,"<>Prévu")) | J17: =IF($C17="",0,SUMIFS(P_M4,P_Annee,Annee_Travail,P_Cat,$C17,P_Type,"Revenu")) | K17: =IF($C17="",0,SUMIFS(J_Montant,J_Annee,Annee_Travail,J_Mois,4,J_Cat,$C17,J_Type,"Revenu",J_Statut,"<>Annulé",J_Statut,"<>Prévu")) | L17: =IF($C17="",0,SUMIFS(P_M5,P_Annee,Annee_Travail,P_Cat,$C17,P_Type,"Revenu")) | M17: =IF($C17="",0,SUMIFS(J_Montant,J_Annee,Annee_Travail,J_Mois,5,J_Cat,$C17,J_Type,"Revenu",J_Statut,"<>Annulé",J_Statut,"<>Prévu")) | N17: =IF($C17="",0,SUMIFS(P_M6,P_Annee,Annee_Travail,P_Cat,$C17,P_Type,"Revenu")) | O17: =IF($C17="",0,SUMIFS(J_Montant,J_Annee,Annee_Travail,J_Mois,6,J_Cat,$C17,J_Type,"Revenu",J_Statut,"<>Annulé",J_Statut,"<>Prévu")) | P17: =IF($C17="",0,SUMIFS(P_M7,P_Annee,Annee_Travail,P_Cat,$C17,P_Type,"Revenu")) | Q17: =IF($C17="",0,SUMIFS(J_Montant,J_Annee,Annee_Travail,J_Mois,7,J_Cat,$C17,J_Type,"Revenu",J_Statut,"<>Annulé",J_Statut,"<>Prévu")) | R17: =IF($C17="",0,SUMIFS(P_M8,P_Annee,Annee_Travail,P_Cat,$C17,P_Type,"Revenu")) | S17: =IF($C17="",0,SUMIFS(J_Montant,J_Annee,Annee_Travail,J_Mois,8,J_Cat,$C17,J_Type,"Revenu",J_Statut,"<>Annulé",J_Statut,"<>Prévu")) | T17: =IF($C17="",0,SUMIFS(P_M9,P_Annee,Annee_Travail,P_Cat,$C17,P_Type,"Revenu")) | U17: =IF($C17="",0,SUMIFS(J_Montant,J_Annee,Annee_Travail,J_Mois,9,J_Cat,$C17,J_Type,"Revenu",J_Statut,"<>Annulé",J_Statut,"<>Prévu")) | V17: =IF($C17="",0,SUMIFS(P_M10,P_Annee,Annee_Travail,P_Cat,$C17,P_Type,"Revenu")) | W17: =IF($C17="",0,SUMIFS(J_Montant,J_Annee,Annee_Travail,J_Mois,10,J_Cat,$C17,J_Type,"Revenu",J_Statut,"<>Annulé",J_Statut,"<>Prévu")) | X17: =IF($C17="",0,SUMIFS(P_M11,P_Annee,Annee_Travail,P_Cat,$C17,P_Type,"Revenu")) | Y17: =IF($C17="",0,SUMIFS(J_Montant,J_Annee,Annee_Travail,J_Mois,11,J_Cat,$C17,J_Type,"Revenu",J_Statut,"<>Annulé",J_Statut,"<>Prévu")) | Z17: =IF($C17="",0,SUMIFS(P_M12,P_Annee,Annee_Travail,P_Cat,$C17,P_Type,"Revenu")) | AA17: =IF($C17="",0,SUMIFS(J_Montant,J_Annee,Annee_Travail,J_Mois,12,J_Cat,$C17,J_Type,"Revenu",J_Statut,"<>Annulé",J_Statut,"<>Prévu")) | AB17: =D17+F17+H17+J17+L17+N17+P17+R17+T17+V17+X17+Z17 | AC17: =E17+G17+I17+K17+M17+O17+Q17+S17+U17+W17+Y17+AA17 | AD17: =$AC17-$AB17 | AE17: =IFERROR($AC17/$AB17,0)
